[2023-06-07T01:15:29.935+0000] {taskinstance.py:1103} INFO - Dependencies all met for dep_context=non-requeueable deps ti=<TaskInstance: open_brewery_pipeline.data_load manual__2023-06-07T01:14:59.165444+00:00 [queued]>
[2023-06-07T01:15:29.950+0000] {taskinstance.py:1103} INFO - Dependencies all met for dep_context=requeueable deps ti=<TaskInstance: open_brewery_pipeline.data_load manual__2023-06-07T01:14:59.165444+00:00 [queued]>
[2023-06-07T01:15:29.951+0000] {taskinstance.py:1308} INFO - Starting attempt 1 of 1
[2023-06-07T01:15:29.970+0000] {taskinstance.py:1327} INFO - Executing <Task(BashOperator): data_load> on 2023-06-07 01:14:59.165444+00:00
[2023-06-07T01:15:29.978+0000] {standard_task_runner.py:57} INFO - Started process 204 to run task
[2023-06-07T01:15:29.984+0000] {standard_task_runner.py:84} INFO - Running: ['***', 'tasks', 'run', 'open_brewery_pipeline', 'data_load', 'manual__2023-06-07T01:14:59.165444+00:00', '--job-id', '57', '--raw', '--subdir', 'DAGS_FOLDER/open_brewery_pipeline.py', '--cfg-path', '/tmp/tmpgfgd8gcs']
[2023-06-07T01:15:29.989+0000] {standard_task_runner.py:85} INFO - Job 57: Subtask data_load
[2023-06-07T01:15:30.057+0000] {task_command.py:410} INFO - Running <TaskInstance: open_brewery_pipeline.data_load manual__2023-06-07T01:14:59.165444+00:00 [running]> on host 258f2d3f7f96
[2023-06-07T01:15:30.190+0000] {taskinstance.py:1547} INFO - Exporting env vars: AIRFLOW_CTX_DAG_OWNER='***' AIRFLOW_CTX_DAG_ID='open_brewery_pipeline' AIRFLOW_CTX_TASK_ID='data_load' AIRFLOW_CTX_EXECUTION_DATE='2023-06-07T01:14:59.165444+00:00' AIRFLOW_CTX_TRY_NUMBER='1' AIRFLOW_CTX_DAG_RUN_ID='manual__2023-06-07T01:14:59.165444+00:00'
[2023-06-07T01:15:30.202+0000] {subprocess.py:63} INFO - Tmp dir root location: 
 /tmp
[2023-06-07T01:15:30.205+0000] {subprocess.py:75} INFO - Running command: ['/bin/bash', '-c', 'python3 /opt/scripts/load.py ']
[2023-06-07T01:15:30.225+0000] {subprocess.py:86} INFO - Output:
[2023-06-07T01:15:31.068+0000] {subprocess.py:93} INFO - Traceback (most recent call last):
[2023-06-07T01:15:31.069+0000] {subprocess.py:93} INFO -   File "/opt/scripts/load.py", line 44, in <module>
[2023-06-07T01:15:31.071+0000] {subprocess.py:93} INFO -     main()
[2023-06-07T01:15:31.072+0000] {subprocess.py:93} INFO -   File "/opt/scripts/load.py", line 41, in main
[2023-06-07T01:15:31.073+0000] {subprocess.py:93} INFO -     upload_blob("open_brewery", "./***/scripts/data.txt", "brewery_data")
[2023-06-07T01:15:31.075+0000] {subprocess.py:93} INFO -   File "/opt/scripts/load.py", line 21, in upload_blob
[2023-06-07T01:15:31.076+0000] {subprocess.py:93} INFO -     storage_client = storage.Client()
[2023-06-07T01:15:31.077+0000] {subprocess.py:93} INFO -   File "/home/***/.local/lib/python3.7/site-packages/google/cloud/storage/client.py", line 177, in __init__
[2023-06-07T01:15:31.078+0000] {subprocess.py:93} INFO -     _http=_http,
[2023-06-07T01:15:31.079+0000] {subprocess.py:93} INFO -   File "/home/***/.local/lib/python3.7/site-packages/google/cloud/client/__init__.py", line 322, in __init__
[2023-06-07T01:15:31.080+0000] {subprocess.py:93} INFO -     self, credentials=credentials, client_options=client_options, _http=_http
[2023-06-07T01:15:31.081+0000] {subprocess.py:93} INFO -   File "/home/***/.local/lib/python3.7/site-packages/google/cloud/client/__init__.py", line 178, in __init__
[2023-06-07T01:15:31.082+0000] {subprocess.py:93} INFO -     credentials, _ = google.auth.default(scopes=scopes)
[2023-06-07T01:15:31.083+0000] {subprocess.py:93} INFO -   File "/home/***/.local/lib/python3.7/site-packages/google/auth/_default.py", line 648, in default
[2023-06-07T01:15:31.084+0000] {subprocess.py:93} INFO -     raise exceptions.DefaultCredentialsError(_CLOUD_SDK_MISSING_CREDENTIALS)
[2023-06-07T01:15:31.085+0000] {subprocess.py:93} INFO - google.auth.exceptions.DefaultCredentialsError: Your default credentials were not found. To set up Application Default Credentials, see https://cloud.google.com/docs/authentication/external/set-up-adc for more information.
[2023-06-07T01:15:31.119+0000] {subprocess.py:97} INFO - Command exited with return code 1
[2023-06-07T01:15:31.137+0000] {taskinstance.py:1824} ERROR - Task failed with exception
Traceback (most recent call last):
  File "/home/airflow/.local/lib/python3.7/site-packages/airflow/operators/bash.py", line 211, in execute
    f"Bash command failed. The command returned a non-zero exit code {result.exit_code}."
airflow.exceptions.AirflowException: Bash command failed. The command returned a non-zero exit code 1.
[2023-06-07T01:15:31.144+0000] {taskinstance.py:1350} INFO - Marking task as FAILED. dag_id=open_brewery_pipeline, task_id=data_load, execution_date=20230607T011459, start_date=20230607T011529, end_date=20230607T011531
[2023-06-07T01:15:31.162+0000] {standard_task_runner.py:109} ERROR - Failed to execute job 57 for task data_load (Bash command failed. The command returned a non-zero exit code 1.; 204)
[2023-06-07T01:15:31.208+0000] {local_task_job_runner.py:225} INFO - Task exited with return code 1
[2023-06-07T01:15:31.234+0000] {taskinstance.py:2651} INFO - 0 downstream tasks scheduled from follow-on schedule check
