[2023-06-07T19:27:44.745+0000] {taskinstance.py:1103} INFO - Dependencies all met for dep_context=non-requeueable deps ti=<TaskInstance: open_brewery_pipeline.data_load manual__2023-06-07T19:26:58.976032+00:00 [queued]>
[2023-06-07T19:27:44.761+0000] {taskinstance.py:1103} INFO - Dependencies all met for dep_context=requeueable deps ti=<TaskInstance: open_brewery_pipeline.data_load manual__2023-06-07T19:26:58.976032+00:00 [queued]>
[2023-06-07T19:27:44.763+0000] {taskinstance.py:1308} INFO - Starting attempt 1 of 1
[2023-06-07T19:27:44.788+0000] {taskinstance.py:1327} INFO - Executing <Task(BashOperator): data_load> on 2023-06-07 19:26:58.976032+00:00
[2023-06-07T19:27:44.798+0000] {standard_task_runner.py:57} INFO - Started process 3632 to run task
[2023-06-07T19:27:44.805+0000] {standard_task_runner.py:84} INFO - Running: ['***', 'tasks', 'run', 'open_brewery_pipeline', 'data_load', 'manual__2023-06-07T19:26:58.976032+00:00', '--job-id', '65', '--raw', '--subdir', 'DAGS_FOLDER/open_brewery_pipeline.py', '--cfg-path', '/tmp/tmp9lvl6_t0']
[2023-06-07T19:27:44.810+0000] {standard_task_runner.py:85} INFO - Job 65: Subtask data_load
[2023-06-07T19:27:44.901+0000] {task_command.py:410} INFO - Running <TaskInstance: open_brewery_pipeline.data_load manual__2023-06-07T19:26:58.976032+00:00 [running]> on host a2d5081e771c
[2023-06-07T19:27:45.065+0000] {taskinstance.py:1547} INFO - Exporting env vars: AIRFLOW_CTX_DAG_OWNER='***' AIRFLOW_CTX_DAG_ID='open_brewery_pipeline' AIRFLOW_CTX_TASK_ID='data_load' AIRFLOW_CTX_EXECUTION_DATE='2023-06-07T19:26:58.976032+00:00' AIRFLOW_CTX_TRY_NUMBER='1' AIRFLOW_CTX_DAG_RUN_ID='manual__2023-06-07T19:26:58.976032+00:00'
[2023-06-07T19:27:45.072+0000] {subprocess.py:63} INFO - Tmp dir root location: 
 /tmp
[2023-06-07T19:27:45.076+0000] {subprocess.py:75} INFO - Running command: ['/bin/bash', '-c', 'python3 /opt/scripts/load.py ']
[2023-06-07T19:27:45.111+0000] {subprocess.py:86} INFO - Output:
[2023-06-07T19:27:48.532+0000] {subprocess.py:93} INFO - /home/***/.local/lib/python3.7/site-packages/google/auth/_default.py:78: UserWarning: Your application has authenticated using end user credentials from Google Cloud SDK without a quota project. You might receive a "quota exceeded" or "API not enabled" error. See the following page for troubleshooting: https://cloud.google.com/docs/authentication/adc-troubleshooting/user-creds.
[2023-06-07T19:27:48.533+0000] {subprocess.py:93} INFO -   warnings.warn(_CLOUD_SDK_CREDENTIALS_WARNING)
[2023-06-07T19:27:48.544+0000] {subprocess.py:93} INFO - Traceback (most recent call last):
[2023-06-07T19:27:48.545+0000] {subprocess.py:93} INFO -   File "/home/***/.local/lib/python3.7/site-packages/google/cloud/storage/blob.py", line 2553, in upload_from_file
[2023-06-07T19:27:48.546+0000] {subprocess.py:93} INFO -     retry=retry,
[2023-06-07T19:27:48.547+0000] {subprocess.py:93} INFO -   File "/home/***/.local/lib/python3.7/site-packages/google/cloud/storage/blob.py", line 2368, in _do_upload
[2023-06-07T19:27:48.548+0000] {subprocess.py:93} INFO -     retry=retry,
[2023-06-07T19:27:48.549+0000] {subprocess.py:93} INFO -   File "/home/***/.local/lib/python3.7/site-packages/google/cloud/storage/blob.py", line 1891, in _do_multipart_upload
[2023-06-07T19:27:48.550+0000] {subprocess.py:93} INFO -     transport, data, object_metadata, content_type, timeout=timeout
[2023-06-07T19:27:48.551+0000] {subprocess.py:93} INFO -   File "/home/***/.local/lib/python3.7/site-packages/google/resumable_media/requests/upload.py", line 154, in transmit
[2023-06-07T19:27:48.552+0000] {subprocess.py:93} INFO -     retriable_request, self._get_status_code, self._retry_strategy
[2023-06-07T19:27:48.553+0000] {subprocess.py:93} INFO -   File "/home/***/.local/lib/python3.7/site-packages/google/resumable_media/requests/_request_helpers.py", line 155, in wait_and_retry
[2023-06-07T19:27:48.555+0000] {subprocess.py:93} INFO -     response = func()
[2023-06-07T19:27:48.556+0000] {subprocess.py:93} INFO -   File "/home/***/.local/lib/python3.7/site-packages/google/resumable_media/requests/upload.py", line 149, in retriable_request
[2023-06-07T19:27:48.557+0000] {subprocess.py:93} INFO -     self._process_response(result)
[2023-06-07T19:27:48.558+0000] {subprocess.py:93} INFO -   File "/home/***/.local/lib/python3.7/site-packages/google/resumable_media/_upload.py", line 114, in _process_response
[2023-06-07T19:27:48.559+0000] {subprocess.py:93} INFO -     _helpers.require_status_code(response, (http.client.OK,), self._get_status_code)
[2023-06-07T19:27:48.560+0000] {subprocess.py:93} INFO -   File "/home/***/.local/lib/python3.7/site-packages/google/resumable_media/_helpers.py", line 113, in require_status_code
[2023-06-07T19:27:48.562+0000] {subprocess.py:93} INFO -     *status_codes
[2023-06-07T19:27:48.563+0000] {subprocess.py:93} INFO - google.resumable_media.common.InvalidResponse: ('Request failed with status code', 412, 'Expected one of', <HTTPStatus.OK: 200>)
[2023-06-07T19:27:48.564+0000] {subprocess.py:93} INFO - 
[2023-06-07T19:27:48.566+0000] {subprocess.py:93} INFO - During handling of the above exception, another exception occurred:
[2023-06-07T19:27:48.567+0000] {subprocess.py:93} INFO - 
[2023-06-07T19:27:48.568+0000] {subprocess.py:93} INFO - Traceback (most recent call last):
[2023-06-07T19:27:48.569+0000] {subprocess.py:93} INFO -   File "/opt/scripts/load.py", line 44, in <module>
[2023-06-07T19:27:48.571+0000] {subprocess.py:93} INFO -     main()
[2023-06-07T19:27:48.572+0000] {subprocess.py:93} INFO -   File "/opt/scripts/load.py", line 41, in main
[2023-06-07T19:27:48.574+0000] {subprocess.py:93} INFO -     upload_blob("open_brewery", "/opt/scripts/data.txt", "brewery_data")
[2023-06-07T19:27:48.576+0000] {subprocess.py:93} INFO -   File "/opt/scripts/load.py", line 33, in upload_blob
[2023-06-07T19:27:48.577+0000] {subprocess.py:93} INFO -     blob.upload_from_filename(source_file_name, if_generation_match=generation_match_precondition)
[2023-06-07T19:27:48.578+0000] {subprocess.py:93} INFO -   File "/home/***/.local/lib/python3.7/site-packages/google/cloud/storage/blob.py", line 2697, in upload_from_filename
[2023-06-07T19:27:48.579+0000] {subprocess.py:93} INFO -     retry=retry,
[2023-06-07T19:27:48.581+0000] {subprocess.py:93} INFO -   File "/home/***/.local/lib/python3.7/site-packages/google/cloud/storage/blob.py", line 2557, in upload_from_file
[2023-06-07T19:27:48.582+0000] {subprocess.py:93} INFO -     _raise_from_invalid_response(exc)
[2023-06-07T19:27:48.583+0000] {subprocess.py:93} INFO -   File "/home/***/.local/lib/python3.7/site-packages/google/cloud/storage/blob.py", line 4369, in _raise_from_invalid_response
[2023-06-07T19:27:48.584+0000] {subprocess.py:93} INFO -     raise exceptions.from_http_status(response.status_code, message, response=response)
[2023-06-07T19:27:48.584+0000] {subprocess.py:93} INFO - google.api_core.exceptions.PreconditionFailed: 412 POST https://storage.googleapis.com/upload/storage/v1/b/open_brewery/o?uploadType=multipart&ifGenerationMatch=0: {
[2023-06-07T19:27:48.585+0000] {subprocess.py:93} INFO -   "error": {
[2023-06-07T19:27:48.587+0000] {subprocess.py:93} INFO -     "code": 412,
[2023-06-07T19:27:48.588+0000] {subprocess.py:93} INFO -     "message": "At least one of the pre-conditions you specified did not hold.",
[2023-06-07T19:27:48.590+0000] {subprocess.py:93} INFO -     "errors": [
[2023-06-07T19:27:48.591+0000] {subprocess.py:93} INFO -       {
[2023-06-07T19:27:48.592+0000] {subprocess.py:93} INFO -         "message": "At least one of the pre-conditions you specified did not hold.",
[2023-06-07T19:27:48.593+0000] {subprocess.py:93} INFO -         "domain": "global",
[2023-06-07T19:27:48.594+0000] {subprocess.py:93} INFO -         "reason": "conditionNotMet",
[2023-06-07T19:27:48.596+0000] {subprocess.py:93} INFO -         "locationType": "header",
[2023-06-07T19:27:48.597+0000] {subprocess.py:93} INFO -         "location": "If-Match"
[2023-06-07T19:27:48.599+0000] {subprocess.py:93} INFO -       }
[2023-06-07T19:27:48.600+0000] {subprocess.py:93} INFO -     ]
[2023-06-07T19:27:48.601+0000] {subprocess.py:93} INFO -   }
[2023-06-07T19:27:48.602+0000] {subprocess.py:93} INFO - }
[2023-06-07T19:27:48.605+0000] {subprocess.py:93} INFO - : ('Request failed with status code', 412, 'Expected one of', <HTTPStatus.OK: 200>)
[2023-06-07T19:27:48.612+0000] {subprocess.py:97} INFO - Command exited with return code 1
[2023-06-07T19:27:48.631+0000] {taskinstance.py:1824} ERROR - Task failed with exception
Traceback (most recent call last):
  File "/home/airflow/.local/lib/python3.7/site-packages/airflow/operators/bash.py", line 211, in execute
    f"Bash command failed. The command returned a non-zero exit code {result.exit_code}."
airflow.exceptions.AirflowException: Bash command failed. The command returned a non-zero exit code 1.
[2023-06-07T19:27:48.639+0000] {taskinstance.py:1350} INFO - Marking task as FAILED. dag_id=open_brewery_pipeline, task_id=data_load, execution_date=20230607T192658, start_date=20230607T192744, end_date=20230607T192748
[2023-06-07T19:27:48.656+0000] {standard_task_runner.py:109} ERROR - Failed to execute job 65 for task data_load (Bash command failed. The command returned a non-zero exit code 1.; 3632)
[2023-06-07T19:27:48.677+0000] {local_task_job_runner.py:225} INFO - Task exited with return code 1
[2023-06-07T19:27:48.705+0000] {taskinstance.py:2651} INFO - 0 downstream tasks scheduled from follow-on schedule check
